Workbook
Name cellLeft: #REF!
Name VALUEVX: LAMBDA(42.314159)

Sheet Septiembre
E1: CONTROL DE CITAS | AN1: Fecha | AO1: Consultorio | AP1: Estado | AQ1: Paciente | AR1: Precio | AS1: Tipo | AT1: Forma1 | AU1: Monto1 | AV1: Forma2 | AW1: Monto2 | AX1: Empleado
E2: Centro Médico Comunitario OscaryAnny | M2: $ USD: | N2: =IFERROR(__xludf.DUMMYFUNCTION("IMPORTXML(""https://www.bcv.org.ve/"", ""//*[@id='dolar']//strong"", ""es_VE"")"),888.8909) -> 888.8909
M3: Fecha Valor: | N3: =IFERROR(__xludf.DUMMYFUNCTION("IMPORTXML(""https://www.bcv.org.ve/"", ""(//span[@class='date-display-single'])[1]"", ""es_VE"")"),46324) -> 46324
A4: 46266 | AE4: TOTAL DEL MES
A5: Hora | B5: Name | C5: Consultorio N° 1 | G5: Consultorio N° 2 | K5: Consultorio N° 3 | S5: Consultorio N° 1 | W5: Consultorio N° 2 | AA5: Consultorio N° 3 | AE5: Doctor | AG5: Cantidad citas | AH5: Citas pagadas | AI5: Total | AJ5: Monto Cobrado | AK5: Monto ADH | AL5: Monto Médico | AN5: Fecha | AO5: Consultorio | AP5: Estado | AQ5: Paciente | AR5: Precio | AS5: Tipo | AT5: Forma 1 | AU5: Monto 1 | AV5: Forma 2 | AW5: Monto 2 | AX5: Empleado | AY5: Doctor | BA5: CONSULTA BENEFICIO DE EMPLEADO DEL MES | BF5: CONSULTAS 50% DESC./ FAMILIAR DIRECTO DEL MES | BL5: CONSULTA BENEFICIO DE PARTICIPANTES ADH DEL MES
A6: =Q12 -> 0.33333333 | E6: Representante: | F6: =IF(D6<>"", VLOOKUP(D6,'Base de Datos'!$A$2:$D1268,2,FALSE()),"") | I6: Representante: | J6: =IF(H6<>"", VLOOKUP(H6,'Base de Datos'!$A$2:$D1268,2,FALSE()),"") | M6: Representante: | N6: =IF(L6<>"", VLOOKUP(L6,'Base de Datos'!$A$2:$D1268,2,FALSE()),"") | T6: Precio: | X6: Precio: | AB6: Precio: | AE6: Dra. Rosanny García | AG6: =COUNTIFS(AP:AP, "💲", AY:AY, AE6) + COUNTIFS(AP:AP, "📦", AY:AY, AE6) + COUNTIFS(AP:AP, "✅", AY:AY, AE6) -> 1 | AH6: =COUNTIFS(AP:AP, "💲", AY:AY, AE6) + COUNTIFS(AP:AP, "📦", AY:AY, AE6) -> 1 | AI6: =SUMIFS(AR:AR, AY:AY, AE6, AP:AP, "💲") + SUMIFS(AR:AR, AY:AY, AE6, AP:AP, "📦") -> 50 | AJ6: =( SUMIFS(AR:AR, AY:AY, INDIRECT("AE" & ROW()), AP:AP, "💲") + SUMIFS(AR:AR, AY:AY, INDIRECT("AE" & ROW()), AP:AP, "📦") ) - ( SUMIFS(AR:AR, AY:AY, INDIRECT("AE" & ROW()), AP:AP, "💲", AS:AS, "Participante") + SUMIFS(AR:AR, AY:AY, INDIRECT("AE" & ROW()), AP:AP, "📦", AS:AS, "Participante") ) - ( SUMIFS(AR:AR, AY:AY, INDIRECT("AE" & ROW()), AP:AP, "💲", AS:AS, "Empleado") + SUMIFS(AR:AR, AY:AY, INDIRECT("AE" & ROW()), AP:AP, "📦", AS:AS, "Empleado") ) - ( ( SUMIFS(AR:AR, AY:AY, INDIRECT("AE" & ROW()), AP:AP, "💲", AS:AS, "Familiar") + SUMIFS(AR:AR, AY:AY, INDIRECT("AE" & ROW()), AP:AP, "📦", AS:AS, "Familiar") ) / 2 ) - ( ( SUMIFS(AR:AR, AY:AY, INDIRECT("AE" & ROW()), AP:AP, "💲", AS:AS, "Exonerado ADH") + SUMIFS(AR:AR, AY:AY, INDIRECT("AE" & ROW()), AP:AP, "📦", AS:AS, "Exonerado ADH") ) / 2 ) - ( ( SUMIFS(AR:AR, AY:AY, INDIRECT("AE" & ROW()), AP:AP, "💲", AS:AS, "Exonerado Doctor") + SUMIFS(AR:AR, AY:AY, INDIRECT("AE" & ROW()), AP:AP, "📦", AS:AS, "Exonerado Doctor") ) / 2 ) -> 0 | AK6: =( SUMIFS(AR:AR, AY:AY, INDIRECT("AE" & ROW()), AP:AP, "💲") + SUMIFS(AR:AR, AY:AY, INDIRECT("AE" & ROW()), AP:AP, "📦") ) - ( SUMIFS(AR:AR, AY:AY, INDIRECT("AE" & ROW()), AP:AP, "💲", AS:AS, "Familiar") + SUMIFS(AR:AR, AY:AY, INDIRECT("AE" & ROW()), AP:AP, "📦", AS:AS, "Familiar") ) - ( SUMIFS(AR:AR, AY:AY, INDIRECT("AE" & ROW()), AP:AP, "💲", AS:AS, "Participante") + SUMIFS(AR:AR, AY:AY, INDIRECT("AE" & ROW()), AP:AP, "📦", AS:AS, "Participante") ) - ( SUMIFS(AR:AR, AY:AY, INDIRECT("AE" & ROW()), AP:AP, "💲", AS:AS, "Empleado") + SUMIFS(AR:AR, AY:AY, INDIRECT("AE" & ROW()), AP:AP, "📦", AS:AS, "Empleado") ) - ( SUMIFS(AR:AR, AY:AY, INDIRECT("AE" & ROW()), AP:AP, "💲", AS:AS, "Exonerado ADH") + SUMIFS(AR:AR, AY:AY, INDIRECT("AE" & ROW()), AP:AP, "📦", AS:AS, "Exonerado ADH") ) - (( SUMIFS(AR:AR, AY:AY, INDIRECT("AE" & ROW()), AP:AP, "💲", AS:AS, "Exonerado Doctor") + SUMIFS(AR:AR, AY:AY, INDIRECT("AE" & ROW()), AP:AP, "📦", AS:AS, "Exonerado Doctor") ) / 2 )- ( ( SUMIFS(AR:AR, AY:AY, INDIRECT("AE" & ROW()), AP:AP, "💲", AS:AS, "") + SUMIFS(AR:AR, AY:AY, INDIRECT("AE" & ROW()), AP:AP, "📦", AS:AS, "") ) / 2 ) -> 0 | AL6: =( SUMIFS(AR:AR, AY:AY, INDIRECT("AE" & ROW()), AP:AP, "💲") + SUMIFS(AR:AR, AY:AY, INDIRECT("AE" & ROW()), AP:AP, "📦") ) - (( SUMIFS(AR:AR, AY:AY, INDIRECT("AE" & ROW()), AP:AP, "💲", AS:AS, "Familiar") + SUMIFS(AR:AR, AY:AY, INDIRECT("AE" & ROW()), AP:AP, "📦", AS:AS, "Familiar") ) / 2 ) - (( SUMIFS(AR:AR, AY:AY, INDIRECT("AE" & ROW()), AP:AP, "💲", AS:AS, "Participante") + SUMIFS(AR:AR, AY:AY, INDIRECT("AE" & ROW()), AP:AP, "📦", AS:AS, "Participante") ) / 2 ) - (( SUMIFS(AR:AR, AY:AY, INDIRECT("AE" & ROW()), AP:AP, "💲", AS:AS, "Empleado") + SUMIFS(AR:AR, AY:AY, INDIRECT("AE" & ROW()), AP:AP, "📦", AS:AS, "Empleado") ) / 2 ) - (( SUMIFS(AR:AR, AY:AY, INDIRECT("AE" & ROW()), AP:AP, "💲", AS:AS, "Exonerado ADH") + SUMIFS(AR:AR, AY:AY, INDIRECT("AE" & ROW()), AP:AP, "📦", AS:AS, "Exonerado ADH") ) / 2 ) - ( SUMIFS(AR:AR, AY:AY, INDIRECT("AE" & ROW()), AP:AP, "💲", AS:AS, "Exonerado Doctor") + SUMIFS(AR:AR, AY:AY, INDIRECT("AE" & ROW()), AP:AP, "📦", AS:AS, "Exonerado Doctor") )- ( ( SUMIFS(AR:AR, AY:AY, INDIRECT("AE" & ROW()), AP:AP, "💲", AS:AS, "") + SUMIFS(AR:AR, AY:AY, INDIRECT("AE" & ROW()), AP:AP, "📦", AS:AS, "") ) / 2 ) -> 25 | AN6: =A4 -> 46266 | AO6: =C5 -> Consultorio N° 1 | AP6: =C6 -> 0 | AQ6: =D6 -> 0 | AR6: =U6 -> 0 | AS6: =S6 -> 0 | AT6: =S7 -> 0 | AU6: =U7 -> 0 | AV6: =S8 -> 0 | AW6: =U8 -> 0 | AX6: =U9 -> 0 | AY6: =F9 -> 0 | BA6: Nombre y Apellido | BB6: Fecha | BC6: Monto | BD6: Doctor | BF6: Nombre y Apellido | BG6: Personal ADH | BH6: Fecha | BI6: Monto | BJ6: Doctor | BL6: Nombre y Apellido | BM6: Fecha | BN6: Monto
E7: Teléfono: | F7: =IF(D6<>"", VLOOKUP(D6,'Base de Datos'!$A$2:$D1268,3,FALSE()),"") | I7: Teléfono: | J7: =IF(H6<>"", VLOOKUP(H6,'Base de Datos'!$A$2:$D1268,3,FALSE()),"") | M7: Teléfono: | N7: =IF(L6<>"", VLOOKUP(L6,'Base de Datos'!$A$2:$D1268,3,FALSE()),"") | AE7: Dra. Maribel Guilarte | AG7: =COUNTIFS(AP:AP, "💲", AY:AY, AE7) + COUNTIFS(AP:AP, "📦", AY:AY, AE7) + COUNTIFS(AP:AP, "✅", AY:AY, AE7) -> 1 | AH7: =COUNTIFS(AP:AP, "💲", AY:AY, AE7) + COUNTIFS(AP:AP, "📦", AY:AY, AE7) -> 1 | AI7: =SUMIFS(AR:AR, AY:AY, AE7, AP:AP, "💲") + SUMIFS(AR:AR, AY:AY, AE7, AP:AP, "📦") -> 50 | AJ7: =( SUMIFS(AR:AR, AY:AY, INDIRECT("AE" & ROW()), AP:AP, "💲") + SUMIFS(AR:AR, AY:AY, INDIRECT("AE" & ROW()), AP:AP, "📦") ) - ( SUMIFS(AR:AR, AY:AY, INDIRECT("AE" & ROW()), AP:AP, "💲", AS:AS, "Participante") + SUMIFS(AR:AR, AY:AY, INDIRECT("AE" & ROW()), AP:AP, "📦", AS:AS, "Participante") ) - ( SUMIFS(AR:AR, AY:AY, INDIRECT("AE" & ROW()), AP:AP, "💲", AS:AS, "Empleado") + SUMIFS(AR:AR, AY:AY, INDIRECT("AE" & ROW()), AP:AP, "📦", AS:AS, "Empleado") ) - ( ( SUMIFS(AR:AR, AY:AY, INDIRECT("AE" & ROW()), AP:AP, "💲", AS:AS, "Familiar") + SUMIFS(AR:AR, AY:AY, INDIRECT("AE" & ROW()), AP:AP, "📦", AS:AS, "Familiar") ) / 2 ) - ( ( SUMIFS(AR:AR, AY:AY, INDIRECT("AE" & ROW()), AP:AP, "💲", AS:AS, "Exonerado ADH") + SUMIFS(AR:AR, AY:AY, INDIRECT("AE" & ROW()), AP:AP, "📦", AS:AS, "Exonerado ADH") ) / 2 ) - ( ( SUMIFS(AR:AR, AY:AY, INDIRECT("AE" & ROW()), AP:AP, "💲", AS:AS, "Exonerado Doctor") + SUMIFS(AR:AR, AY:AY, INDIRECT("AE" & ROW()), AP:AP, "📦", AS:AS, "Exonerado Doctor") ) / 2 ) -> 0 | AK7: =( SUMIFS(AR:AR, AY:AY, INDIRECT("AE" & ROW()), AP:AP, "💲") + SUMIFS(AR:AR, AY:AY, INDIRECT("AE" & ROW()), AP:AP, "📦") ) - ( SUMIFS(AR:AR, AY:AY, INDIRECT("AE" & ROW()), AP:AP, "💲", AS:AS, "Familiar") + SUMIFS(AR:AR, AY:AY, INDIRECT("AE" & ROW()), AP:AP, "📦", AS:AS, "Familiar") ) - ( SUMIFS(AR:AR, AY:AY, INDIRECT("AE" & ROW()), AP:AP, "💲", AS:AS, "Participante") + SUMIFS(AR:AR, AY:AY, INDIRECT("AE" & ROW()), AP:AP, "📦", AS:AS, "Participante") ) - ( SUMIFS(AR:AR, AY:AY, INDIRECT("AE" & ROW()), AP:AP, "💲", AS:AS, "Empleado") + SUMIFS(AR:AR, AY:AY, INDIRECT("AE" & ROW()), AP:AP, "📦", AS:AS, "Empleado") ) - ( SUMIFS(AR:AR, AY:AY, INDIRECT("AE" & ROW()), AP:AP, "💲", AS:AS, "Exonerado ADH") + SUMIFS(AR:AR, AY:AY, INDIRECT("AE" & ROW()), AP:AP, "📦", AS:AS, "Exonerado ADH") ) - (( SUMIFS(AR:AR, AY:AY, INDIRECT("AE" & ROW()), AP:AP, "💲", AS:AS, "Exonerado Doctor") + SUMIFS(AR:AR, AY:AY, INDIRECT("AE" & ROW()), AP:AP, "📦", AS:AS, "Exonerado Doctor") ) / 2 )- ( ( SUMIFS(AR:AR, AY:AY, INDIRECT("AE" & ROW()), AP:AP, "💲", AS:AS, "") + SUMIFS(AR:AR, AY:AY, INDIRECT("AE" & ROW()), AP:AP, "📦", AS:AS, "") ) / 2 ) -> 0 | AL7: =( SUMIFS(AR:AR, AY:AY, INDIRECT("AE" & ROW()), AP:AP, "💲") + SUMIFS(AR:AR, AY:AY, INDIRECT("AE" & ROW()), AP:AP, "📦") ) - (( SUMIFS(AR:AR, AY:AY, INDIRECT("AE" & ROW()), AP:AP, "💲", AS:AS, "Familiar") + SUMIFS(AR:AR, AY:AY, INDIRECT("AE" & ROW()), AP:AP, "📦", AS:AS, "Familiar") ) / 2 ) - (( SUMIFS(AR:AR, AY:AY, INDIRECT("AE" & ROW()), AP:AP, "💲", AS:AS, "Participante") + SUMIFS(AR:AR, AY:AY, INDIRECT("AE" & ROW()), AP:AP, "📦", AS:AS, "Participante") ) / 2 ) - (( SUMIFS(AR:AR, AY:AY, INDIRECT("AE" & ROW()), AP:AP, "💲", AS:AS, "Empleado") + SUMIFS(AR:AR, AY:AY, INDIRECT("AE" & ROW()), AP:AP, "📦", AS:AS, "Empleado") ) / 2 ) - (( SUMIFS(AR:AR, AY:AY, INDIRECT("AE" & ROW()), AP:AP, "💲", AS:AS, "Exonerado ADH") + SUMIFS(AR:AR, AY:AY, INDIRECT("AE" & ROW()), AP:AP, "📦", AS:AS, "Exonerado ADH") ) / 2 ) - ( SUMIFS(AR:AR, AY:AY, INDIRECT("AE" & ROW()), AP:AP, "💲", AS:AS, "Exonerado Doctor") + SUMIFS(AR:AR, AY:AY, INDIRECT("AE" & ROW()), AP:AP, "📦", AS:AS, "Exonerado Doctor") )- ( ( SUMIFS(AR:AR, AY:AY, INDIRECT("AE" & ROW()), AP:AP, "💲", AS:AS, "") + SUMIFS(AR:AR, AY:AY, INDIRECT("AE" & ROW()), AP:AP, "📦", AS:AS, "") ) / 2 ) -> 25 | AN7: =A4 -> 46266 | AO7: =C5 -> Consultorio N° 1 | AP7: =C10 -> 0 | AQ7: =D10 -> 0 | AR7: =U10 -> 0 | AS7: =S10 -> 0 | AT7: =S11 -> 0 | AU7: =U11 -> 0 | AV7: =S12 -> 0 | AW7: =U12 -> 0 | AX7: =U13 -> 0 | AY7: =F13 -> 0 | BA7: =IFERROR(__xludf.DUMMYFUNCTION("QUERY(AN:AY, ""SELECT AQ, AN, AR, AY WHERE AS = 'Empleado' AND (AP = '💲' OR AP = '📦') ORDER BY AN"", )"),"Silvia D´Angelo") -> Silvia D´Angelo | BB7: =IFERROR(__xludf.DUMMYFUNCTION("""COMPUTED_VALUE"""),46273) -> 46273 | BC7: =IFERROR(__xludf.DUMMYFUNCTION("""COMPUTED_VALUE"""),50) -> 50 | BD7: =IFERROR(__xludf.DUMMYFUNCTION("""COMPUTED_VALUE"""),"Dra. Mónica Porras") -> Dra. Mónica Porras | BF7: =IFERROR(__xludf.DUMMYFUNCTION("QUERY(AN:AY, ""SELECT AQ, AX, AN, AR, AY WHERE AS = 'Familiar' AND (AP = '💲' OR AP = '📦') ORDER BY AN"", )"),"Carla Segura") -> Carla Segura | BH7: =IFERROR(__xludf.DUMMYFUNCTION("""COMPUTED_VALUE"""),46280) -> 46280 | BI7: =IFERROR(__xludf.DUMMYFUNCTION("""COMPUTED_VALUE"""),50) -> 50 | BJ7: =IFERROR(__xludf.DUMMYFUNCTION("""COMPUTED_VALUE"""),"Dra. Mónica Porras") -> Dra. Mónica Porras | BL7: =IFERROR(__xludf.DUMMYFUNCTION("QUERY(AN:AY, ""SELECT AQ, AN, AR WHERE AS = 'Participante' AND (AP = '💲' OR AP = '📦') ORDER BY AN"", )"),"Moises Rodriguez") -> Moises Rodriguez | BM7: =IFERROR(__xludf.DUMMYFUNCTION("""COMPUTED_VALUE"""),46272) -> 46272 | BN7: =IFERROR(__xludf.DUMMYFUNCTION("""COMPUTED_VALUE"""),50) -> 50
E8: Cedula: | F8: =IF(D6<>"", VLOOKUP(D6,'Base de Datos'!$A$2:$D1268,4,FALSE()),"") | I8: Cedula: | J8: =IF(H6<>"", VLOOKUP(H6,'Base de Datos'!$A$2:$D1268,4,FALSE()),"") | M8: Cedula: | N8: =IF(L6<>"", VLOOKUP(L6,'Base de Datos'!$A$2:$D1268,4,FALSE()),"") | AE8: Dra. Lyl Belisario | AG8: =COUNTIFS(AP:AP, "💲", AY:AY, AE8) + COUNTIFS(AP:AP, "📦", AY:AY, AE8) + COUNTIFS(AP:AP, "✅", AY:AY, AE8) -> 0 | AH8: =COUNTIFS(AP:AP, "💲", AY:AY, AE8) + COUNTIFS(AP:AP, "📦", AY:AY, AE8) -> 0 | AI8: =SUMIFS(AR:AR, AY:AY, AE8, AP:AP, "💲") + SUMIFS(AR:AR, AY:AY, AE8, AP:AP, "📦") -> 0 | AJ8: =( SUMIFS(AR:AR, AY:AY, INDIRECT("AE" & ROW()), AP:AP, "💲") + SUMIFS(AR:AR, AY:AY, INDIRECT("AE" & ROW()), AP:AP, "📦") ) - ( SUMIFS(AR:AR, AY:AY, INDIRECT("AE" & ROW()), AP:AP, "💲", AS:AS, "Participante") + SUMIFS(AR:AR, AY:AY, INDIRECT("AE" & ROW()), AP:AP, "📦", AS:AS, "Participante") ) - ( SUMIFS(AR:AR, AY:AY, INDIRECT("AE" & ROW()), AP:AP, "💲", AS:AS, "Empleado") + SUMIFS(AR:AR, AY:AY, INDIRECT("AE" & ROW()), AP:AP, "📦", AS:AS, "Empleado") ) - ( ( SUMIFS(AR:AR, AY:AY, INDIRECT("AE" & ROW()), AP:AP, "💲", AS:AS, "Familiar") + SUMIFS(AR:AR, AY:AY, INDIRECT("AE" & ROW()), AP:AP, "📦", AS:AS, "Familiar") ) / 2 ) - ( ( SUMIFS(AR:AR, AY:AY, INDIRECT("AE" & ROW()), AP:AP, "💲", AS:AS, "Exonerado ADH") + SUMIFS(AR:AR, AY:AY, INDIRECT("AE" & ROW()), AP:AP, "📦", AS:AS, "Exonerado ADH") ) / 2 ) - ( ( SUMIFS(AR:AR, AY:AY, INDIRECT("AE" & ROW()), AP:AP, "💲", AS:AS, "Exonerado Doctor") + SUMIFS(AR:AR, AY:AY, INDIRECT("AE" & ROW()), AP:AP, "📦", AS:AS, "Exonerado Doctor") ) / 2 ) -> 0 | AK8: =( SUMIFS(AR:AR, AY:AY, INDIRECT("AE" & ROW()), AP:AP, "💲") + SUMIFS(AR:AR, AY:AY, INDIRECT("AE" & ROW()), AP:AP, "📦") ) - ( SUMIFS(AR:AR, AY:AY, INDIRECT("AE" & ROW()), AP:AP, "💲", AS:AS, "Familiar") + SUMIFS(AR:AR, AY:AY, INDIRECT("AE" & ROW()), AP:AP, "📦", AS:AS, "Familiar") ) - ( SUMIFS(AR:AR, AY:AY, INDIRECT("AE" & ROW()), AP:AP, "💲", AS:AS, "Participante") + SUMIFS(AR:AR, AY:AY, INDIRECT("AE" & ROW()), AP:AP, "📦", AS:AS, "Participante") ) - ( SUMIFS(AR:AR, AY:AY, INDIRECT("AE" & ROW()), AP:AP, "💲", AS:AS, "Empleado") + SUMIFS(AR:AR, AY:AY, INDIRECT("AE" & ROW()), AP:AP, "📦", AS:AS, "Empleado") ) - ( SUMIFS(AR:AR, AY:AY, INDIRECT("AE" & ROW()), AP:AP, "💲", AS:AS, "Exonerado ADH") + SUMIFS(AR:AR, AY:AY, INDIRECT("AE" & ROW()), AP:AP, "📦", AS:AS, "Exonerado ADH") ) - (( SUMIFS(AR:AR, AY:AY, INDIRECT("AE" & ROW()), AP:AP, "💲", AS:AS, "Exonerado Doctor") + SUMIFS(AR:AR, AY:AY, INDIRECT("AE" & ROW()), AP:AP, "📦", AS:AS, "Exonerado Doctor") ) / 2 )- ( ( SUMIFS(AR:AR, AY:AY, INDIRECT("AE" & ROW()), AP:AP, "💲", AS:AS, "") + SUMIFS(AR:AR, AY:AY, INDIRECT("AE" & ROW()), AP:AP, "📦", AS:AS, "") ) / 2 ) -> 0 | AL8: =( SUMIFS(AR:AR, AY:AY, INDIRECT("AE" & ROW()), AP:AP, "💲") + SUMIFS(AR:AR, AY:AY, INDIRECT("AE" & ROW()), AP:AP, "📦") ) - (( SUMIFS(AR:AR, AY:AY, INDIRECT("AE" & ROW()), AP:AP, "💲", AS:AS, "Familiar") + SUMIFS(AR:AR, AY:AY, INDIRECT("AE" & ROW()), AP:AP, "📦", AS:AS, "Familiar") ) / 2 ) - (( SUMIFS(AR:AR, AY:AY, INDIRECT("AE" & ROW()), AP:AP, "💲", AS:AS, "Participante") + SUMIFS(AR:AR, AY:AY, INDIRECT("AE" & ROW()), AP:AP, "📦", AS:AS, "Participante") ) / 2 ) - (( SUMIFS(AR:AR, AY:AY, INDIRECT("AE" & ROW()), AP:AP, "💲", AS:AS, "Empleado") + SUMIFS(AR:AR, AY:AY, INDIRECT("AE" & ROW()), AP:AP, "📦", AS:AS, "Empleado") ) / 2 ) - (( SUMIFS(AR:AR, AY:AY, INDIRECT("AE" & ROW()), AP:AP, "💲", AS:AS, "Exonerado ADH") + SUMIFS(AR:AR, AY:AY, INDIRECT("AE" & ROW()), AP:AP, "📦", AS:AS, "Exonerado ADH") ) / 2 ) - ( SUMIFS(AR:AR, AY:AY, INDIRECT("AE" & ROW()), AP:AP, "💲", AS:AS, "Exonerado Doctor") + SUMIFS(AR:AR, AY:AY, INDIRECT("AE" & ROW()), AP:AP, "📦", AS:AS, "Exonerado Doctor") )- ( ( SUMIFS(AR:AR, AY:AY, INDIRECT("AE" & ROW()), AP:AP, "💲", AS:AS, "") + SUMIFS(AR:AR, AY:AY, INDIRECT("AE" & ROW()), AP:AP, "📦", AS:AS, "") ) / 2 ) -> 0 | AN8: =A4 -> 46266 | AO8: =C5 -> Consultorio N° 1 | AP8: =C14 -> 0 | AQ8: =D14 -> 0 | AR8: =U14 -> 0 | AS8: =S14 -> 0 | AT8: =S15 -> 0 | AU8: =U15 -> 0 | AV8: =S16 -> 0 | AW8: =U16 -> 0 | AX8: =U17 -> 0 | AY8: =F17 -> 0 | BA8: =IFERROR(__xludf.DUMMYFUNCTION("""COMPUTED_VALUE"""),"Gabriela Guerra") -> Gabriela Guerra | BB8: =IFERROR(__xludf.DUMMYFUNCTION("""COMPUTED_VALUE"""),46274) -> 46274 | BC8: =IFERROR(__xludf.DUMMYFUNCTION("""COMPUTED_VALUE"""),50) -> 50 | BD8: =IFERROR(__xludf.DUMMYFUNCTION("""COMPUTED_VALUE"""),"Dra. Ma.Auxliliadora Aguilera") -> Dra. Ma.Auxliliadora Aguilera | BF8: =IFERROR(__xludf.DUMMYFUNCTION("""COMPUTED_VALUE"""),"Jorgelina Alvarez") -> Jorgelina Alvarez | BH8: =IFERROR(__xludf.DUMMYFUNCTION("""COMPUTED_VALUE"""),46289) -> 46289 | BI8: =IFERROR(__xludf.DUMMYFUNCTION("""COMPUTED_VALUE"""),50) -> 50 | BJ8: =IFERROR(__xludf.DUMMYFUNCTION("""COMPUTED_VALUE"""),"Dr. Jorge Valeri") -> Dr. Jorge Valeri | BL8: =IFERROR(__xludf.DUMMYFUNCTION("""COMPUTED_VALUE"""),"Juan Andres Figueira") -> Juan Andres Figueira | BM8: =IFERROR(__xludf.DUMMYFUNCTION("""COMPUTED_VALUE"""),46280) -> 46280 | BN8: =IFERROR(__xludf.DUMMYFUNCTION("""COMPUTED_VALUE"""),50) -> 50
E9: Doctor: | I9: Doctor: | M9: Doctor: | S9: =IF(OR(S6="Empleado",S6="Familiar"),"Nombre del Empleado","N° Factura") -> N° Factura | W9: =IF(OR(W6="Empleado",W6="Familiar"),"Nombre del Empleado","N° Factura") -> N° Factura | AA9: =IF(OR(AA6="Empleado",AA6="Familiar"),"Nombre del Empleado","N° Factura") -> N° Factura | AE9: Dra. Ma.Auxliliadora Aguilera | AG9: =COUNTIFS(AP:AP, "💲", AY:AY, AE9) + COUNTIFS(AP:AP, "📦", AY:AY, AE9) + COUNTIFS(AP:AP, "✅", AY:AY, AE9) -> 2 | AH9: =COUNTIFS(AP:AP, "💲", AY:AY, AE9) + COUNTIFS(AP:AP, "📦", AY:AY, AE9) -> 2 | AI9: =SUMIFS(AR:AR, AY:AY, AE9, AP:AP, "💲") + SUMIFS(AR:AR, AY:AY, AE9, AP:AP, "📦") -> 100 | AJ9: =( SUMIFS(AR:AR, AY:AY, INDIRECT("AE" & ROW()), AP:AP, "💲") + SUMIFS(AR:AR, AY:AY, INDIRECT("AE" & ROW()), AP:AP, "📦") ) - ( SUMIFS(AR:AR, AY:AY, INDIRECT("AE" & ROW()), AP:AP, "💲", AS:AS, "Participante") + SUMIFS(AR:AR, AY:AY, INDIRECT("AE" & ROW()), AP:AP, "📦", AS:AS, "Participante") ) - ( SUMIFS(AR:AR, AY:AY, INDIRECT("AE" & ROW()), AP:AP, "💲", AS:AS, "Empleado") + SUMIFS(AR:AR, AY:AY, INDIRECT("AE" & ROW()), AP:AP, "📦", AS:AS, "Empleado") ) - ( ( SUMIFS(AR:AR, AY:AY, INDIRECT("AE" & ROW()), AP:AP, "💲", AS:AS, "Familiar") + SUMIFS(AR:AR, AY:AY, INDIRECT("AE" & ROW()), AP:AP, "📦", AS:AS, "Familiar") ) / 2 ) - ( ( SUMIFS(AR:AR, AY:AY, INDIRECT("AE" & ROW()), AP:AP, "💲", AS:AS, "Exonerado ADH") + SUMIFS(AR:AR, AY:AY, INDIRECT("AE" & ROW()), AP:AP, "📦", AS:AS, "Exonerado ADH") ) / 2 ) - ( ( SUMIFS(AR:AR, AY:AY, INDIRECT("AE" & ROW()), AP:AP, "💲", AS:AS, "Exonerado Doctor") + SUMIFS(AR:AR, AY:AY, INDIRECT("AE" & ROW()), AP:AP, "📦", AS:AS, "Exonerado Doctor") ) / 2 ) -> 25 | AK9: =( SUMIFS(AR:AR, AY:AY, INDIRECT("AE" & ROW()), AP:AP, "💲") + SUMIFS(AR:AR, AY:AY, INDIRECT("AE" & ROW()), AP:AP, "📦") ) - ( SUMIFS(AR:AR, AY:AY, INDIRECT("AE" & ROW()), AP:AP, "💲", AS:AS, "Familiar") + SUMIFS(AR:AR, AY:AY, INDIRECT("AE" & ROW()), AP:AP, "📦", AS:AS, "Familiar") ) - ( SUMIFS(AR:AR, AY:AY, INDIRECT("AE" & ROW()), AP:AP, "💲", AS:AS, "Participante") + SUMIFS(AR:AR, AY:AY, INDIRECT("AE" & ROW()), AP:AP, "📦", AS:AS, "Participante") ) - ( SUMIFS(AR:AR, AY:AY, INDIRECT("AE" & ROW()), AP:AP, "💲", AS:AS, "Empleado") + SUMIFS(AR:AR, AY:AY, INDIRECT("AE" & ROW()), AP:AP, "📦", AS:AS, "Empleado") ) - ( SUMIFS(AR:AR, AY:AY, INDIRECT("AE" & ROW()), AP:AP, "💲", AS:AS, "Exonerado ADH") + SUMIFS(AR:AR, AY:AY, INDIRECT("AE" & ROW()), AP:AP, "📦", AS:AS, "Exonerado ADH") ) - (( SUMIFS(AR:AR, AY:AY, INDIRECT("AE" & ROW()), AP:AP, "💲", AS:AS, "Exonerado Doctor") + SUMIFS(AR:AR, AY:AY, INDIRECT("AE" & ROW()), AP:AP, "📦", AS:AS, "Exonerado Doctor") ) / 2 )- ( ( SUMIFS(AR:AR, AY:AY, INDIRECT("AE" & ROW()), AP:AP, "💲", AS:AS, "") + SUMIFS(AR:AR, AY:AY, INDIRECT("AE" & ROW()), AP:AP, "📦", AS:AS, "") ) / 2 ) -> 0 | AL9: =( SUMIFS(AR:AR, AY:AY, INDIRECT("AE" & ROW()), AP:AP, "💲") + SUMIFS(AR:AR, AY:AY, INDIRECT("AE" & ROW()), AP:AP, "📦") ) - (( SUMIFS(AR:AR, AY:AY, INDIRECT("AE" & ROW()), AP:AP, "💲", AS:AS, "Familiar") + SUMIFS(AR:AR, AY:AY, INDIRECT("AE" & ROW()), AP:AP, "📦", AS:AS, "Familiar") ) / 2 ) - (( SUMIFS(AR:AR, AY:AY, INDIRECT("AE" & ROW()), AP:AP, "💲", AS:AS, "Participante") + SUMIFS(AR:AR, AY:AY, INDIRECT("AE" & ROW()), AP:AP, "📦", AS:AS, "Participante") ) / 2 ) - (( SUMIFS(AR:AR, AY:AY, INDIRECT("AE" & ROW()), AP:AP, "💲", AS:AS, "Empleado") + SUMIFS(AR:AR, AY:AY, INDIRECT("AE" & ROW()), AP:AP, "📦", AS:AS, "Empleado") ) / 2 ) - (( SUMIFS(AR:AR, AY:AY, INDIRECT("AE" & ROW()), AP:AP, "💲", AS:AS, "Exonerado ADH") + SUMIFS(AR:AR, AY:AY, INDIRECT("AE" & ROW()), AP:AP, "📦", AS:AS, "Exonerado ADH") ) / 2 ) - ( SUMIFS(AR:AR, AY:AY, INDIRECT("AE" & ROW()), AP:AP, "💲", AS:AS, "Exonerado Doctor") + SUMIFS(AR:AR, AY:AY, INDIRECT("AE" & ROW()), AP:AP, "📦", AS:AS, "Exonerado Doctor") )- ( ( SUMIFS(AR:AR, AY:AY, INDIRECT("AE" & ROW()), AP:AP, "💲", AS:AS, "") + SUMIFS(AR:AR, AY:AY, INDIRECT("AE" & ROW()), AP:AP, "📦", AS:AS, "") ) / 2 ) -> 50 | AN9: =A4 -> 46266 | AO9: =C5 -> Consultorio N° 1 | AP9: =C18 -> 0 | AQ9: =D18 -> 0 | AR9: =U18 -> 0 | AS9: =S18 -> 0 | AT9: =S19 -> 0 | AU9: =U19 -> 0 | AV9: =S20 -> 0 | AW9: =U20 -> 0 | AX9: =U21 -> 0 | AY9: =F21 -> 0 | BA9: =IFERROR(__xludf.DUMMYFUNCTION("""COMPUTED_VALUE"""),"Jorgelina Alvarez") -> Jorgelina Alvarez | BB9: =IFERROR(__xludf.DUMMYFUNCTION("""COMPUTED_VALUE"""),46274) -> 46274 | BC9: =IFERROR(__xludf.DUMMYFUNCTION("""COMPUTED_VALUE"""),50) -> 50 | BD9: =IFERROR(__xludf.DUMMYFUNCTION("""COMPUTED_VALUE"""),"Dra. Gabriela Berbis") -> Dra. Gabriela Berbis | BF9: =IFERROR(__xludf.DUMMYFUNCTION("""COMPUTED_VALUE"""),"Leonardo Aular") -> Leonardo Aular | BH9: =IFERROR(__xludf.DUMMYFUNCTION("""COMPUTED_VALUE"""),46293) -> 46293 | BI9: =IFERROR(__xludf.DUMMYFUNCTION("""COMPUTED_VALUE"""),50) -> 50 | BJ9: =IFERROR(__xludf.DUMMYFUNCTION("""COMPUTED_VALUE"""),"Luzmir Fagúndez") -> Luzmir Fagúndez | BL9: =IFERROR(__xludf.DUMMYFUNCTION("""COMPUTED_VALUE"""),"Juan Carlos Keklikian") -> Juan Carlos Keklikian | BM9: =IFERROR(__xludf.DUMMYFUNCTION("""COMPUTED_VALUE"""),46282) -> 46282 | BN9: =IFERROR(__xludf.DUMMYFUNCTION("""COMPUTED_VALUE"""),50) -> 50
A10: =A6+$Q$13/1440 -> 0.375 | E10: Representante: | F10: =IF(D10<>"", VLOOKUP(D10,'Base de Datos'!$A$2:$D1268,2,FALSE()),"") | I10: Representante: | J10: =IF(H10<>"", VLOOKUP(H10,'Base de Datos'!$A$2:$D1268,2,FALSE()),"") | M10: Representante: | N10: =IF(L10<>"", VLOOKUP(L10,'Base de Datos'!$A$2:$D1268,2,FALSE()),"") | O10: $ USD: | Q10: =$N$2 -> 888.8909 | T10: Precio: | X10: Precio: | AB10: Precio: | AE10: Dr. Jorge Valeri | AG10: =COUNTIFS(AP:AP, "💲", AY:AY, AE10) + COUNTIFS(AP:AP, "📦", AY:AY, AE10) + COUNTIFS(AP:AP, "✅", AY:AY, AE10) -> 11 | AH10: =COUNTIFS(AP:AP, "💲", AY:AY, AE10) + COUNTIFS(AP:AP, "📦", AY:AY, AE10) -> 11 | AI10: =SUMIFS(AR:AR, AY:AY, AE10, AP:AP, "💲") + SUMIFS(AR:AR, AY:AY, AE10, AP:AP, "📦") -> 550 | AJ10: =( SUMIFS(AR:AR, AY:AY, INDIRECT("AE" & ROW()), AP:AP, "💲") + SUMIFS(AR:AR, AY:AY, INDIRECT("AE" & ROW()), AP:AP, "📦") ) - ( SUMIFS(AR:AR, AY:AY, INDIRECT("AE" & ROW()), AP:AP, "💲", AS:AS, "Participante") + SUMIFS(AR:AR, AY:AY, INDIRECT("AE" & ROW()), AP:AP, "📦", AS:AS, "Participante") ) - ( SUMIFS(AR:AR, AY:AY, INDIRECT("AE" & ROW()), AP:AP, "💲", AS:AS, "Empleado") + SUMIFS(AR:AR, AY:AY, INDIRECT("AE" & ROW()), AP:AP, "📦", AS:AS, "Empleado") ) - ( ( SUMIFS(AR:AR, AY:AY, INDIRECT("AE" & ROW()), AP:AP, "💲", AS:AS, "Familiar") + SUMIFS(AR:AR, AY:AY, INDIRECT("AE" & ROW()), AP:AP, "📦", AS:AS, "Familiar") ) / 2 ) - ( ( SUMIFS(AR:AR, AY:AY, INDIRECT("AE" & ROW()), AP:AP, "💲", AS:AS, "Exonerado ADH") + SUMIFS(AR:AR, AY:AY, INDIRECT("AE" & ROW()), AP:AP, "📦", AS:AS, "Exonerado ADH") ) / 2 ) - ( ( SUMIFS(AR:AR, AY:AY, INDIRECT("AE" & ROW()), AP:AP, "💲", AS:AS, "Exonerado Doctor") + SUMIFS(AR:AR, AY:AY, INDIRECT("AE" & ROW()), AP:AP, "📦", AS:AS, "Exonerado Doctor") ) / 2 ) -> 425 | AK10: =( SUMIFS(AR:AR, AY:AY, INDIRECT("AE" & ROW()), AP:AP, "💲") + SUMIFS(AR:AR, AY:AY, INDIRECT("AE" & ROW()), AP:AP, "📦") ) - ( SUMIFS(AR:AR, AY:AY, INDIRECT("AE" & ROW()), AP:AP, "💲", AS:AS, "Familiar") + SUMIFS(AR:AR, AY:AY, INDIRECT("AE" & ROW()), AP:AP, "📦", AS:AS, "Familiar") ) - ( SUMIFS(AR:AR, AY:AY, INDIRECT("AE" & ROW()), AP:AP, "💲", AS:AS, "Participante") + SUMIFS(AR:AR, AY:AY, INDIRECT("AE" & ROW()), AP:AP, "📦", AS:AS, "Participante") ) - ( SUMIFS(AR:AR, AY:AY, INDIRECT("AE" & ROW()), AP:AP, "💲", AS:AS, "Empleado") + SUMIFS(AR:AR, AY:AY, INDIRECT("AE" & ROW()), AP:AP, "📦", AS:AS, "Empleado") ) - ( SUMIFS(AR:AR, AY:AY, INDIRECT("AE" & ROW()), AP:AP, "💲", AS:AS, "Exonerado ADH") + SUMIFS(AR:AR, AY:AY, INDIRECT("AE" & ROW()), AP:AP, "📦", AS:AS, "Exonerado ADH") ) - (( SUMIFS(AR:AR, AY:AY, INDIRECT("AE" & ROW()), AP:AP, "💲", AS:AS, "Exonerado Doctor") + SUMIFS(AR:AR, AY:AY, INDIRECT("AE" & ROW()), AP:AP, "📦", AS:AS, "Exonerado Doctor") ) / 2 )- ( ( SUMIFS(AR:AR, AY:AY, INDIRECT("AE" & ROW()), AP:AP, "💲", AS:AS, "") + SUMIFS(AR:AR, AY:AY, INDIRECT("AE" & ROW()), AP:AP, "📦", AS:AS, "") ) / 2 ) -> 400 | AL10: =( SUMIFS(AR:AR, AY:AY, INDIRECT("AE" & ROW()), AP:AP, "💲") + SUMIFS(AR:AR, AY:AY, INDIRECT("AE" & ROW()), AP:AP, "📦") ) - (( SUMIFS(AR:AR, AY:AY, INDIRECT("AE" & ROW()), AP:AP, "💲", AS:AS, "Familiar") + SUMIFS(AR:AR, AY:AY, INDIRECT("AE" & ROW()), AP:AP, "📦", AS:AS, "Familiar") ) / 2 ) - (( SUMIFS(AR:AR, AY:AY, INDIRECT("AE" & ROW()), AP:AP, "💲", AS:AS, "Participante") + SUMIFS(AR:AR, AY:AY, INDIRECT("AE" & ROW()), AP:AP, "📦", AS:AS, "Participante") ) / 2 ) - (( SUMIFS(AR:AR, AY:AY, INDIRECT("AE" & ROW()), AP:AP, "💲", AS:AS, "Empleado") + SUMIFS(AR:AR, AY:AY, INDIRECT("AE" & ROW()), AP:AP, "📦", AS:AS, "Empleado") ) / 2 ) - (( SUMIFS(AR:AR, AY:AY, INDIRECT("AE" & ROW()), AP:AP, "💲", AS:AS, "Exonerado ADH") + SUMIFS(AR:AR, AY:AY, INDIRECT("AE" & ROW()), AP:AP, "📦", AS:AS, "Exonerado ADH") ) / 2 ) - ( SUMIFS(AR:AR, AY:AY, INDIRECT("AE" & ROW()), AP:AP, "💲", AS:AS, "Exonerado Doctor") + SUMIFS(AR:AR, AY:AY, INDIRECT("AE" & ROW()), AP:AP, "📦", AS:AS, "Exonerado Doctor") )- ( ( SUMIFS(AR:AR, AY:AY, INDIRECT("AE" & ROW()), AP:AP, "💲", AS:AS, "") + SUMIFS(AR:AR, AY:AY, INDIRECT("AE" & ROW()), AP:AP, "📦", AS:AS, "") ) / 2 ) -> 475 | AN10: =A4 -> 46266 | AO10: =C5 -> Consultorio N° 1 | AP10: =C22 -> 0 | AQ10: =D22 -> 0 | AR10: =U22 -> 0 | AS10: =S22 -> 0 | AT10: =S23 -> 0 | AU10: =U23 -> 0 | AV10: =S24 -> 0 | AW10: =U24 -> 0 | AX10: =U25 -> 0 | AY10: =F25 -> 0 | BA10: =IFERROR(__xludf.DUMMYFUNCTION("""COMPUTED_VALUE"""),"Dariela Cáceres") -> Dariela Cáceres | BB10: =IFERROR(__xludf.DUMMYFUNCTION("""COMPUTED_VALUE"""),46276) -> 46276 | BC10: =IFERROR(__xludf.DUMMYFUNCTION("""COMPUTED_VALUE"""),50) -> 50 | BD10: =IFERROR(__xludf.DUMMYFUNCTION("""COMPUTED_VALUE"""),"Odo. Geraldine Cabrera") -> Odo. Geraldine Cabrera | BL10: =IFERROR(__xludf.DUMMYFUNCTION("""COMPUTED_VALUE"""),"Ignacio Escorcia") -> Ignacio Escorcia | BM10: =IFERROR(__xludf.DUMMYFUNCTION("""COMPUTED_VALUE"""),46282) -> 46282 | BN10: =IFERROR(__xludf.DUMMYFUNCTION("""COMPUTED_VALUE"""),50) -> 50
E11: Teléfono: | F11: =IF(D10<>"", VLOOKUP(D10,'Base de Datos'!$A$2:$D1268,3,FALSE()),"") | I11: Teléfono: | J11: =IF(H10<>"", VLOOKUP(H10,'Base de Datos'!$A$2:$D1268,3,FALSE()),"") | M11: Teléfono: | N11: =IF(L10<>"", VLOOKUP(L10,'Base de Datos'!$A$2:$D1268,3,FALSE()),"") | AE11: Dr. José Francisco Cordero | AG11: =COUNTIFS(AP:AP, "💲", AY:AY, AE11) + COUNTIFS(AP:AP, "📦", AY:AY, AE11) + COUNTIFS(AP:AP, "✅", AY:AY, AE11) -> 0 | AH11: =COUNTIFS(AP:AP, "💲", AY:AY, AE11) + COUNTIFS(AP:AP, "📦", AY:AY, AE11) -> 0 | AI11: =SUMIFS(AR:AR, AY:AY, AE11, AP:AP, "💲") + SUMIFS(AR:AR, AY:AY, AE11, AP:AP, "📦") -> 0 | AJ11: =( SUMIFS(AR:AR, AY:AY, INDIRECT("AE" & ROW()), AP:AP, "💲") + SUMIFS(AR:AR, AY:AY, INDIRECT("AE" & ROW()), AP:AP, "📦") ) - ( SUMIFS(AR:AR, AY:AY, INDIRECT("AE" & ROW()), AP:AP, "💲", AS:AS, "Participante") + SUMIFS(AR:AR, AY:AY, INDIRECT("AE" & ROW()), AP:AP, "📦", AS:AS, "Participante") ) - ( SUMIFS(AR:AR, AY:AY, INDIRECT("AE" & ROW()), AP:AP, "💲", AS:AS, "Empleado") + SUMIFS(AR:AR, AY:AY, INDIRECT("AE" & ROW()), AP:AP, "📦", AS:AS, "Empleado") ) - ( ( SUMIFS(AR:AR, AY:AY, INDIRECT("AE" & ROW()), AP:AP, "💲", AS:AS, "Familiar") + SUMIFS(AR:AR, AY:AY, INDIRECT("AE" & ROW()), AP:AP, "📦", AS:AS, "Familiar") ) / 2 ) - ( ( SUMIFS(AR:AR, AY:AY, INDIRECT("AE" & ROW()), AP:AP, "💲", AS:AS, "Exonerado ADH") + SUMIFS(AR:AR, AY:AY, INDIRECT("AE" & ROW()), AP:AP, "📦", AS:AS, "Exonerado ADH") ) / 2 ) - ( ( SUMIFS(AR:AR, AY:AY, INDIRECT("AE" & ROW()), AP:AP, "💲", AS:AS, "Exonerado Doctor") + SUMIFS(AR:AR, AY:AY, INDIRECT("AE" & ROW()), AP:AP, "📦", AS:AS, "Exonerado Doctor") ) / 2 ) -> 0 | AK11: =( SUMIFS(AR:AR, AY:AY, INDIRECT("AE" & ROW()), AP:AP, "💲") + SUMIFS(AR:AR, AY:AY, INDIRECT("AE" & ROW()), AP:AP, "📦") ) - ( SUMIFS(AR:AR, AY:AY, INDIRECT("AE" & ROW()), AP:AP, "💲", AS:AS, "Familiar") + SUMIFS(AR:AR, AY:AY, INDIRECT("AE" & ROW()), AP:AP, "📦", AS:AS, "Familiar") ) - ( SUMIFS(AR:AR, AY:AY, INDIRECT("AE" & ROW()), AP:AP, "💲", AS:AS, "Participante") + SUMIFS(AR:AR, AY:AY, INDIRECT("AE" & ROW()), AP:AP, "📦", AS:AS, "Participante") ) - ( SUMIFS(AR:AR, AY:AY, INDIRECT("AE" & ROW()), AP:AP, "💲", AS:AS, "Empleado") + SUMIFS(AR:AR, AY:AY, INDIRECT("AE" & ROW()), AP:AP, "📦", AS:AS, "Empleado") ) - ( SUMIFS(AR:AR, AY:AY, INDIRECT("AE" & ROW()), AP:AP, "💲", AS:AS, "Exonerado ADH") + SUMIFS(AR:AR, AY:AY, INDIRECT("AE" & ROW()), AP:AP, "📦", AS:AS, "Exonerado ADH") ) - (( SUMIFS(AR:AR, AY:AY, INDIRECT("AE" & ROW()), AP:AP, "💲", AS:AS, "Exonerado Doctor") + SUMIFS(AR:AR, AY:AY, INDIRECT("AE" & ROW()), AP:AP, "📦", AS:AS, "Exonerado Doctor") ) / 2 )- ( ( SUMIFS(AR:AR, AY:AY, INDIRECT("AE" & ROW()), AP:AP, "💲", AS:AS, "") + SUMIFS(AR:AR, AY:AY, INDIRECT("AE" & ROW()), AP:AP, "📦", AS:AS, "") ) / 2 ) -> 0 | AL11: =( SUMIFS(AR:AR, AY:AY, INDIRECT("AE" & ROW()), AP:AP, "💲") + SUMIFS(AR:AR, AY:AY, INDIRECT("AE" & ROW()), AP:AP, "📦") ) - (( SUMIFS(AR:AR, AY:AY, INDIRECT("AE" & ROW()), AP:AP, "💲", AS:AS, "Familiar") + SUMIFS(AR:AR, AY:AY, INDIRECT("AE" & ROW()), AP:AP, "📦", AS:AS, "Familiar") ) / 2 ) - (( SUMIFS(AR:AR, AY:AY, INDIRECT("AE" & ROW()), AP:AP, "💲", AS:AS, "Participante") + SUMIFS(AR:AR, AY:AY, INDIRECT("AE" & ROW()), AP:AP, "📦", AS:AS, "Participante") ) / 2 ) - (( SUMIFS(AR:AR, AY:AY, INDIRECT("AE" & ROW()), AP:AP, "💲", AS:AS, "Empleado") + SUMIFS(AR:AR, AY:AY, INDIRECT("AE" & ROW()), AP:AP, "📦", AS:AS, "Empleado") ) / 2 ) - (( SUMIFS(AR:AR, AY:AY, INDIRECT("AE" & ROW()), AP:AP, "💲", AS:AS, "Exonerado ADH") + SUMIFS(AR:AR, AY:AY, INDIRECT("AE" & ROW()), AP:AP, "📦", AS:AS, "Exonerado ADH") ) / 2 ) - ( SUMIFS(AR:AR, AY:AY, INDIRECT("AE" & ROW()), AP:AP, "💲", AS:AS, "Exonerado Doctor") + SUMIFS(AR:AR, AY:AY, INDIRECT("AE" & ROW()), AP:AP, "📦", AS:AS, "Exonerado Doctor") )- ( ( SUMIFS(AR:AR, AY:AY, INDIRECT("AE" & ROW()), AP:AP, "💲", AS:AS, "") + SUMIFS(AR:AR, AY:AY, INDIRECT("AE" & ROW()), AP:AP, "📦", AS:AS, "") ) / 2 ) -> 0 | AN11: =A4 -> 46266 | AO11: =C5 -> Consultorio N° 1 | AP11: =C26 -> 0 | AQ11: =D26 -> 0 | AR11: =U26 -> 0 | AS11: =S26 -> 0 | AT11: =S27 -> 0 | AU11: =U27 -> 0 | AV11: =S28 -> 0 | AW11: =U28 -> 0 | AX11: =U29 -> 0 | AY11: =F29 -> 0 | BA11: =IFERROR(__xludf.DUMMYFUNCTION("""COMPUTED_VALUE"""),"Marly Bracamontes") -> Marly Bracamontes | BB11: =IFERROR(__xludf.DUMMYFUNCTION("""COMPUTED_VALUE"""),46276) -> 46276 | BC11: =IFERROR(__xludf.DUMMYFUNCTION("""COMPUTED_VALUE"""),50) -> 50 | BD11: =IFERROR(__xludf.DUMMYFUNCTION("""COMPUTED_VALUE"""),"Odo. Geraldine Cabrera") -> Odo. Geraldine Cabrera | BL11: =IFERROR(__xludf.DUMMYFUNCTION("""COMPUTED_VALUE"""),"Luis Daniel La Cruz") -> Luis Daniel La Cruz | BM11: =IFERROR(__xludf.DUMMYFUNCTION("""COMPUTED_VALUE"""),46289) -> 46289 | BN11: =IFERROR(__xludf.DUMMYFUNCTION("""COMPUTED_VALUE"""),50) -> 50
E12: Cedula: | F12: =IF(D10<>"", VLOOKUP(D10,'Base de Datos'!$A$2:$D1268,4,FALSE()),"") | I12: Cedula: | J12: =IF(H10<>"", VLOOKUP(H10,'Base de Datos'!$A$2:$D1268,4,FALSE()),"") | M12: Cedula: | N12: =IF(L10<>"", VLOOKUP(L10,'Base de Datos'!$A$2:$D1268,4,FALSE()),"") | P12: Hora de inicio | Q12: 0.33333333 | AE12: Dra. Mónica Porras | AG12: =COUNTIFS(AP:AP, "💲", AY:AY, AE12) + COUNTIFS(AP:AP, "📦", AY:AY, AE12) + COUNTIFS(AP:AP, "✅", AY:AY, AE12) -> 3 | AH12: =COUNTIFS(AP:AP, "💲", AY:AY, AE12) + COUNTIFS(AP:AP, "📦", AY:AY, AE12) -> 3 | AI12: =SUMIFS(AR:AR, AY:AY, AE12, AP:AP, "💲") + SUMIFS(AR:AR, AY:AY, AE12, AP:AP, "📦") -> 150 | AJ12: =( SUMIFS(AR:AR, AY:AY, INDIRECT("AE" & ROW()), AP:AP, "💲") + SUMIFS(AR:AR, AY:AY, INDIRECT("AE" & ROW()), AP:AP, "📦") ) - ( SUMIFS(AR:AR, AY:AY, INDIRECT("AE" & ROW()), AP:AP, "💲", AS:AS, "Participante") + SUMIFS(AR:AR, AY:AY, INDIRECT("AE" & ROW()), AP:AP, "📦", AS:AS, "Participante") ) - ( SUMIFS(AR:AR, AY:AY, INDIRECT("AE" & ROW()), AP:AP, "💲", AS:AS, "Empleado") + SUMIFS(AR:AR, AY:AY, INDIRECT("AE" & ROW()), AP:AP, "📦", AS:AS, "Empleado") ) - ( ( SUMIFS(AR:AR, AY:AY, INDIRECT("AE" & ROW()), AP:AP, "💲", AS:AS, "Familiar") + SUMIFS(AR:AR, AY:AY, INDIRECT("AE" & ROW()), AP:AP, "📦", AS:AS, "Familiar") ) / 2 ) - ( ( SUMIFS(AR:AR, AY:AY, INDIRECT("AE" & ROW()), AP:AP, "💲", AS:AS, "Exonerado ADH") + SUMIFS(AR:AR, AY:AY, INDIRECT("AE" & ROW()), AP:AP, "📦", AS:AS, "Exonerado ADH") ) / 2 ) - ( ( SUMIFS(AR:AR, AY:AY, INDIRECT("AE" & ROW()), AP:AP, "💲", AS:AS, "Exonerado Doctor") + SUMIFS(AR:AR, AY:AY, INDIRECT("AE" & ROW()), AP:AP, "📦", AS:AS, "Exonerado Doctor") ) / 2 ) -> 75 | AK12: =( SUMIFS(AR:AR, AY:AY, INDIRECT("AE" & ROW()), AP:AP, "💲") + SUMIFS(AR:AR, AY:AY, INDIRECT("AE" & ROW()), AP:AP, "📦") ) - ( SUMIFS(AR:AR, AY:AY, INDIRECT("AE" & ROW()), AP:AP, "💲", AS:AS, "Familiar") + SUMIFS(AR:AR, AY:AY, INDIRECT("AE" & ROW()), AP:AP, "📦", AS:AS, "Familiar") ) - ( SUMIFS(AR:AR, AY:AY, INDIRECT("AE" & ROW()), AP:AP, "💲", AS:AS, "Participante") + SUMIFS(AR:AR, AY:AY, INDIRECT("AE" & ROW()), AP:AP, "📦", AS:AS, "Participante") ) - ( SUMIFS(AR:AR, AY:AY, INDIRECT("AE" & ROW()), AP:AP, "💲", AS:AS, "Empleado") + SUMIFS(AR:AR, AY:AY, INDIRECT("AE" & ROW()), AP:AP, "📦", AS:AS, "Empleado") ) - ( SUMIFS(AR:AR, AY:AY, INDIRECT("AE" & ROW()), AP:AP, "💲", AS:AS, "Exonerado ADH") + SUMIFS(AR:AR, AY:AY, INDIRECT("AE" & ROW()), AP:AP, "📦", AS:AS, "Exonerado ADH") ) - (( SUMIFS(AR:AR, AY:AY, INDIRECT("AE" & ROW()), AP:AP, "💲", AS:AS, "Exonerado Doctor") + SUMIFS(AR:AR, AY:AY, INDIRECT("AE" & ROW()), AP:AP, "📦", AS:AS, "Exonerado Doctor") ) / 2 )- ( ( SUMIFS(AR:AR, AY:AY, INDIRECT("AE" & ROW()), AP:AP, "💲", AS:AS, "") + SUMIFS(AR:AR, AY:AY, INDIRECT("AE" & ROW()), AP:AP, "📦", AS:AS, "") ) / 2 ) -> 50 | AL12: =( SUMIFS(AR:AR, AY:AY, INDIRECT("AE" & ROW()), AP:AP, "💲") + SUMIFS(AR:AR, AY:AY, INDIRECT("AE" & ROW()), AP:AP, "📦") ) - (( SUMIFS(AR:AR, AY:AY, INDIRECT("AE" & ROW()), AP:AP, "💲", AS:AS, "Familiar") + SUMIFS(AR:AR, AY:AY, INDIRECT("AE" & ROW()), AP:AP, "📦", AS:AS, "Familiar") ) / 2 ) - (( SUMIFS(AR:AR, AY:AY, INDIRECT("AE" & ROW()), AP:AP, "💲", AS:AS, "Participante") + SUMIFS(AR:AR, AY:AY, INDIRECT("AE" & ROW()), AP:AP, "📦", AS:AS, "Participante") ) / 2 ) - (( SUMIFS(AR:AR, AY:AY, INDIRECT("AE" & ROW()), AP:AP, "💲", AS:AS, "Empleado") + SUMIFS(AR:AR, AY:AY, INDIRECT("AE" & ROW()), AP:AP, "📦", AS:AS, "Empleado") ) / 2 ) - (( SUMIFS(AR:AR, AY:AY, INDIRECT("AE" & ROW()), AP:AP, "💲", AS:AS, "Exonerado ADH") + SUMIFS(AR:AR, AY:AY, INDIRECT("AE" & ROW()), AP:AP, "📦", AS:AS, "Exonerado ADH") ) / 2 ) - ( SUMIFS(AR:AR, AY:AY, INDIRECT("AE" & ROW()), AP:AP, "💲", AS:AS, "Exonerado Doctor") + SUMIFS(AR:AR, AY:AY, INDIRECT("AE" & ROW()), AP:AP, "📦", AS:AS, "Exonerado Doctor") )- ( ( SUMIFS(AR:AR, AY:AY, INDIRECT("AE" & ROW()), AP:AP, "💲", AS:AS, "") + SUMIFS(AR:AR, AY:AY, INDIRECT("AE" & ROW()), AP:AP, "📦", AS:AS, "") ) / 2 ) -> 100 | AN12: =A4 -> 46266 | AO12: =C5 -> Consultorio N° 1 | AP12: =C30 -> 0 | AQ12: =D30 -> 0 | AR12: =U30 -> 0 | AS12: =S30 -> 0 | AT12: =S31 -> 0 | AU12: =U31 -> 0 | AV12: =S32 -> 0 | AW12: =U32 -> 0 | AX12: =U33 -> 0 | AY12: =F33 -> 0 | BA12: =IFERROR(__xludf.DUMMYFUNCTION("""COMPUTED_VALUE"""),"Johanna Lopez") -> Johanna Lopez | BB12: =IFERROR(__xludf.DUMMYFUNCTION("""COMPUTED_VALUE"""),46289) -> 46289 | BC12: =IFERROR(__xludf.DUMMYFUNCTION("""COMPUTED_VALUE"""),50) -> 50 | BD12: =IFERROR(__xludf.DUMMYFUNCTION("""COMPUTED_VALUE"""),"Dra. Conchita Sánchez") -> Dra. Conchita Sánchez
E13: Doctor: | I13: Doctor: | M13: Doctor: | P13: Intervalo | Q13: 60 | S13: =IF(OR(S10="Empleado",S10="Familiar"),"Nombre del Empleado","N° Factura") -> N° Factura | W13: =IF(OR(W10="Empleado",W10="Familiar"),"Nombre del Empleado","N° Factura") -> N° Factura | AA13: =IF(OR(AA10="Empleado",AA10="Familiar"),"Nombre del Empleado","N° Factura") -> N° Factura | AE13: Dra. Conchita Sánchez | AG13: =COUNTIFS(AP:AP, "💲", AY:AY, AE13) + COUNTIFS(AP:AP, "📦", AY:AY, AE13) + COUNTIFS(AP:AP, "✅", AY:AY, AE13) -> 3 | AH13: =COUNTIFS(AP:AP, "💲", AY:AY, AE13) + COUNTIFS(AP:AP, "📦", AY:AY, AE13) -> 3 | AI13: =SUMIFS(AR:AR, AY:AY, AE13, AP:AP, "💲") + SUMIFS(AR:AR, AY:AY, AE13, AP:AP, "📦") -> 150 | AJ13: =( SUMIFS(AR:AR, AY:AY, INDIRECT("AE" & ROW()), AP:AP, "💲") + SUMIFS(AR:AR, AY:AY, INDIRECT("AE" & ROW()), AP:AP, "📦") ) - ( SUMIFS(AR:AR, AY:AY, INDIRECT("AE" & ROW()), AP:AP, "💲", AS:AS, "Participante") + SUMIFS(AR:AR, AY:AY, INDIRECT("AE" & ROW()), AP:AP, "📦", AS:AS, "Participante") ) - ( SUMIFS(AR:AR, AY:AY, INDIRECT("AE" & ROW()), AP:AP, "💲", AS:AS, "Empleado") + SUMIFS(AR:AR, AY:AY, INDIRECT("AE" & ROW()), AP:AP, "📦", AS:AS, "Empleado") ) - ( ( SUMIFS(AR:AR, AY:AY, INDIRECT("AE" & ROW()), AP:AP, "💲", AS:AS, "Familiar") + SUMIFS(AR:AR, AY:AY, INDIRECT("AE" & ROW()), AP:AP, "📦", AS:AS, "Familiar") ) / 2 ) - ( ( SUMIFS(AR:AR, AY:AY, INDIRECT("AE" & ROW()), AP:AP, "💲", AS:AS, "Exonerado ADH") + SUMIFS(AR:AR, AY:AY, INDIRECT("AE" & ROW()), AP:AP, "📦", AS:AS, "Exonerado ADH") ) / 2 ) - ( ( SUMIFS(AR:AR, AY:AY, INDIRECT("AE" & ROW()), AP:AP, "💲", AS:AS, "Exonerado Doctor") + SUMIFS(AR:AR, AY:AY, INDIRECT("AE" & ROW()), AP:AP, "📦", AS:AS, "Exonerado Doctor") ) / 2 ) -> 50 | AK13: =( SUMIFS(AR:AR, AY:AY, INDIRECT("AE" & ROW()), AP:AP, "💲") + SUMIFS(AR:AR, AY:AY, INDIRECT("AE" & ROW()), AP:AP, "📦") ) - ( SUMIFS(AR:AR, AY:AY, INDIRECT("AE" & ROW()), AP:AP, "💲", AS:AS, "Familiar") + SUMIFS(AR:AR, AY:AY, INDIRECT("AE" & ROW()), AP:AP, "📦", AS:AS, "Familiar") ) - ( SUMIFS(AR:AR, AY:AY, INDIRECT("AE" & ROW()), AP:AP, "💲", AS:AS, "Participante") + SUMIFS(AR:AR, AY:AY, INDIRECT("AE" & ROW()), AP:AP, "📦", AS:AS, "Participante") ) - ( SUMIFS(AR:AR, AY:AY, INDIRECT("AE" & ROW()), AP:AP, "💲", AS:AS, "Empleado") + SUMIFS(AR:AR, AY:AY, INDIRECT("AE" & ROW()), AP:AP, "📦", AS:AS, "Empleado") ) - ( SUMIFS(AR:AR, AY:AY, INDIRECT("AE" & ROW()), AP:AP, "💲", AS:AS, "Exonerado ADH") + SUMIFS(AR:AR, AY:AY, INDIRECT("AE" & ROW()), AP:AP, "📦", AS:AS, "Exonerado ADH") ) - (( SUMIFS(AR:AR, AY:AY, INDIRECT("AE" & ROW()), AP:AP, "💲", AS:AS, "Exonerado Doctor") + SUMIFS(AR:AR, AY:AY, INDIRECT("AE" & ROW()), AP:AP, "📦", AS:AS, "Exonerado Doctor") ) / 2 )- ( ( SUMIFS(AR:AR, AY:AY, INDIRECT("AE" & ROW()), AP:AP, "💲", AS:AS, "") + SUMIFS(AR:AR, AY:AY, INDIRECT("AE" & ROW()), AP:AP, "📦", AS:AS, "") ) / 2 ) -> 50 | AL13: =( SUMIFS(AR:AR, AY:AY, INDIRECT("AE" & ROW()), AP:AP, "💲") + SUMIFS(AR:AR, AY:AY, INDIRECT("AE" & ROW()), AP:AP, "📦") ) - (( SUMIFS(AR:AR, AY:AY, INDIRECT("AE" & ROW()), AP:AP, "💲", AS:AS, "Familiar") + SUMIFS(AR:AR, AY:AY, INDIRECT("AE" & ROW()), AP:AP, "📦", AS:AS, "Familiar") ) / 2 ) - (( SUMIFS(AR:AR, AY:AY, INDIRECT("AE" & ROW()), AP:AP, "💲", AS:AS, "Participante") + SUMIFS(AR:AR, AY:AY, INDIRECT("AE" & ROW()), AP:AP, "📦", AS:AS, "Participante") ) / 2 ) - (( SUMIFS(AR:AR, AY:AY, INDIRECT("AE" & ROW()), AP:AP, "💲", AS:AS, "Empleado") + SUMIFS(AR:AR, AY:AY, INDIRECT("AE" & ROW()), AP:AP, "📦", AS:AS, "Empleado") ) / 2 ) - (( SUMIFS(AR:AR, AY:AY, INDIRECT("AE" & ROW()), AP:AP, "💲", AS:AS, "Exonerado ADH") + SUMIFS(AR:AR, AY:AY, INDIRECT("AE" & ROW()), AP:AP, "📦", AS:AS, "Exonerado ADH") ) / 2 ) - ( SUMIFS(AR:AR, AY:AY, INDIRECT("AE" & ROW()), AP:AP, "💲", AS:AS, "Exonerado Doctor") + SUMIFS(AR:AR, AY:AY, INDIRECT("AE" & ROW()), AP:AP, "📦", AS:AS, "Exonerado Doctor") )- ( ( SUMIFS(AR:AR, AY:AY, INDIRECT("AE" & ROW()), AP:AP, "💲", AS:AS, "") + SUMIFS(AR:AR, AY:AY, INDIRECT("AE" & ROW()), AP:AP, "📦", AS:AS, "") ) / 2 ) -> 100 | AN13: =A4 -> 46266 | AO13: =C5 -> Consultorio N° 1 | AP13: =C34 -> 0 | AQ13: =D34 -> 0 | AR13: =U34 -> 0 | AS13: =S34 -> 0 | AT13: =S35 -> 0 | AU13: =U35 -> 0 | AV13: =S36 -> 0 | AW13: =U36 -> 0 | AX13: =U37 -> 0 | AY13: =F37 -> 0 | BA13: =IFERROR(__xludf.DUMMYFUNCTION("""COMPUTED_VALUE"""),"Maria Carmela Hernandez") -> Maria Carmela Hernandez | BB13: =IFERROR(__xludf.DUMMYFUNCTION("""COMPUTED_VALUE"""),46290) -> 46290 | BC13: =IFERROR(__xludf.DUMMYFUNCTION("""COMPUTED_VALUE"""),50) -> 50 | BD13: =IFERROR(__xludf.DUMMYFUNCTION("""COMPUTED_VALUE"""),"Odo. Geraldine Cabrera") -> Odo. Geraldine Cabrera
A14: =A10+$Q$13/1440 -> 0.41666667 | E14: Representante: | F14: =IF(D14<>"", VLOOKUP(D14,'Base de Datos'!$A$2:$D1268,2,FALSE()),"") | G14: 🚫 | H14: Yolimar Sofia Sayago Mosqueda | I14: Representante: | J14: =IF(H14<>"", VLOOKUP(H14,'Base de Datos'!$A$2:$D1268,2,FALSE()),"") -> Yolimar Sofia Sayago Mosqueda | M14: Representante: | N14: =IF(L14<>"", VLOOKUP(L14,'Base de Datos'!$A$2:$D1268,2,FALSE()),"") | T14: Precio: | X14: Precio: | AB14: Precio: | AE14: Dr. Carlos Eduardo Márquez | AG14: =COUNTIFS(AP:AP, "💲", AY:AY, AE14) + COUNTIFS(AP:AP, "📦", AY:AY, AE14) + COUNTIFS(AP:AP, "✅", AY:AY, AE14) -> 0 | AH14: =COUNTIFS(AP:AP, "💲", AY:AY, AE14) + COUNTIFS(AP:AP, "📦", AY:AY, AE14) -> 0 | AI14: =SUMIFS(AR:AR, AY:AY, AE14, AP:AP, "💲") + SUMIFS(AR:AR, AY:AY, AE14, AP:AP, "📦") -> 0 | AJ14: =( SUMIFS(AR:AR, AY:AY, INDIRECT("AE" & ROW()), AP:AP, "💲") + SUMIFS(AR:AR, AY:AY, INDIRECT("AE" & ROW()), AP:AP, "📦") ) - ( SUMIFS(AR:AR, AY:AY, INDIRECT("AE" & ROW()), AP:AP, "💲", AS:AS, "Participante") + SUMIFS(AR:AR, AY:AY, INDIRECT("AE" & ROW()), AP:AP, "📦", AS:AS, "Participante") ) - ( SUMIFS(AR:AR, AY:AY, INDIRECT("AE" & ROW()), AP:AP, "💲", AS:AS, "Empleado") + SUMIFS(AR:AR, AY:AY, INDIRECT("AE" & ROW()), AP:AP, "📦", AS:AS, "Empleado") ) - ( ( SUMIFS(AR:AR, AY:AY, INDIRECT("AE" & ROW()), AP:AP, "💲", AS:AS, "Familiar") + SUMIFS(AR:AR, AY:AY, INDIRECT("AE" & ROW()), AP:AP, "📦", AS:AS, "Familiar") ) / 2 ) - ( ( SUMIFS(AR:AR, AY:AY, INDIRECT("AE" & ROW()), AP:AP, "💲", AS:AS, "Exonerado ADH") + SUMIFS(AR:AR, AY:AY, INDIRECT("AE" & ROW()), AP:AP, "📦", AS:AS, "Exonerado ADH") ) / 2 ) - ( ( SUMIFS(AR:AR, AY:AY, INDIRECT("AE" & ROW()), AP:AP, "💲", AS:AS, "Exonerado Doctor") + SUMIFS(AR:AR, AY:AY, INDIRECT("AE" & ROW()), AP:AP, "📦", AS:AS, "Exonerado Doctor") ) / 2 ) -> 0 | AK14: =( SUMIFS(AR:AR, AY:AY, INDIRECT("AE" & ROW()), AP:AP, "💲") + SUMIFS(AR:AR, AY:AY, INDIRECT("AE" & ROW()), AP:AP, "📦") ) - ( SUMIFS(AR:AR, AY:AY, INDIRECT("AE" & ROW()), AP:AP, "💲", AS:AS, "Familiar") + SUMIFS(AR:AR, AY:AY, INDIRECT("AE" & ROW()), AP:AP, "📦", AS:AS, "Familiar") ) - ( SUMIFS(AR:AR, AY:AY, INDIRECT("AE" & ROW()), AP:AP, "💲", AS:AS, "Participante") + SUMIFS(AR:AR, AY:AY, INDIRECT("AE" & ROW()), AP:AP, "📦", AS:AS, "Participante") ) - ( SUMIFS(AR:AR, AY:AY, INDIRECT("AE" & ROW()), AP:AP, "💲", AS:AS, "Empleado") + SUMIFS(AR:AR, AY:AY, INDIRECT("AE" & ROW()), AP:AP, "📦", AS:AS, "Empleado") ) - ( SUMIFS(AR:AR, AY:AY, INDIRECT("AE" & ROW()), AP:AP, "💲", AS:AS, "Exonerado ADH") + SUMIFS(AR:AR, AY:AY, INDIRECT("AE" & ROW()), AP:AP, "📦", AS:AS, "Exonerado ADH") ) - (( SUMIFS(AR:AR, AY:AY, INDIRECT("AE" & ROW()), AP:AP, "💲", AS:AS, "Exonerado Doctor") + SUMIFS(AR:AR, AY:AY, INDIRECT("AE" & ROW()), AP:AP, "📦", AS:AS, "Exonerado Doctor") ) / 2 )- ( ( SUMIFS(AR:AR, AY:AY, INDIRECT("AE" & ROW()), AP:AP, "💲", AS:AS, "") + SUMIFS(AR:AR, AY:AY, INDIRECT("AE" & ROW()), AP:AP, "📦", AS:AS, "") ) / 2 ) -> 0 | AL14: =( SUMIFS(AR:AR, AY:AY, INDIRECT("AE" & ROW()), AP:AP, "💲") + SUMIFS(AR:AR, AY:AY, INDIRECT("AE" & ROW()), AP:AP, "📦") ) - (( SUMIFS(AR:AR, AY:AY, INDIRECT("AE" & ROW()), AP:AP, "💲", AS:AS, "Familiar") + SUMIFS(AR:AR, AY:AY, INDIRECT("AE" & ROW()), AP:AP, "📦", AS:AS, "Familiar") ) / 2 ) - (( SUMIFS(AR:AR, AY:AY, INDIRECT("AE" & ROW()), AP:AP, "💲", AS:AS, "Participante") + SUMIFS(AR:AR, AY:AY, INDIRECT("AE" & ROW()), AP:AP, "📦", AS:AS, "Participante") ) / 2 ) - (( SUMIFS(AR:AR, AY:AY, INDIRECT("AE" & ROW()), AP:AP, "💲", AS:AS, "Empleado") + SUMIFS(AR:AR, AY:AY, INDIRECT("AE" & ROW()), AP:AP, "📦", AS:AS, "Empleado") ) / 2 ) - (( SUMIFS(AR:AR, AY:AY, INDIRECT("AE" & ROW()), AP:AP, "💲", AS:AS, "Exonerado ADH") + SUMIFS(AR:AR, AY:AY, INDIRECT("AE" & ROW()), AP:AP, "📦", AS:AS, "Exonerado ADH") ) / 2 ) - ( SUMIFS(AR:AR, AY:AY, INDIRECT("AE" & ROW()), AP:AP, "💲", AS:AS, "Exonerado Doctor") + SUMIFS(AR:AR, AY:AY, INDIRECT("AE" & ROW()), AP:AP, "📦", AS:AS, "Exonerado Doctor") )- ( ( SUMIFS(AR:AR, AY:AY, INDIRECT("AE" & ROW()), AP:AP, "💲", AS:AS, "") + SUMIFS(AR:AR, AY:AY, INDIRECT("AE" & ROW()), AP:AP, "📦", AS:AS, "") ) / 2 ) -> 0 | AN14: =A4 -> 46266 | AO14: =C5 -> Consultorio N° 1 | AP14: =C38 -> 0 | AQ14: =D38 -> 0 | AR14: =U38 -> 0 | AS14: =S38 -> 0 | AT14: =S39 -> 0 | AU14: =U39 -> 0 | AV14: =S40 -> 0 | AW14: =U40 -> 0 | AX14: =U41 -> 0 | AY14: =F41 -> 0 | BF14: CLIENTES POR PUBLICIDAD DEL MES
E15: Teléfono: | F15: =IF(D14<>"", VLOOKUP(D14,'Base de Datos'!$A$2:$D1268,3,FALSE()),"") | I15: Teléfono: | J15: =IF(H14<>"", VLOOKUP(H14,'Base de Datos'!$A$2:$D1268,3,FALSE()),"") -> 0 | M15: Teléfono: | N15: =IF(L14<>"", VLOOKUP(L14,'Base de Datos'!$A$2:$D1268,3,FALSE()),"") | P15: LEYENDA | AE15: Odo. Geraldine Cabrera | AG15: =COUNTIFS(AP:AP, "💲", AY:AY, AE15) + COUNTIFS(AP:AP, "📦", AY:AY, AE15) + COUNTIFS(AP:AP, "✅", AY:AY, AE15) -> 9 | AH15: =COUNTIFS(AP:AP, "💲", AY:AY, AE15) + COUNTIFS(AP:AP, "📦", AY:AY, AE15) -> 8 | AI15: =SUMIFS(AR:AR, AY:AY, AE15, AP:AP, "💲") + SUMIFS(AR:AR, AY:AY, AE15, AP:AP, "📦") -> 500 | AJ15: =( SUMIFS(AR:AR, AY:AY, INDIRECT("AE" & ROW()), AP:AP, "💲") + SUMIFS(AR:AR, AY:AY, INDIRECT("AE" & ROW()), AP:AP, "📦") ) - ( SUMIFS(AR:AR, AY:AY, INDIRECT("AE" & ROW()), AP:AP, "💲", AS:AS, "Participante") + SUMIFS(AR:AR, AY:AY, INDIRECT("AE" & ROW()), AP:AP, "📦", AS:AS, "Participante") ) - ( SUMIFS(AR:AR, AY:AY, INDIRECT("AE" & ROW()), AP:AP, "💲", AS:AS, "Empleado") + SUMIFS(AR:AR, AY:AY, INDIRECT("AE" & ROW()), AP:AP, "📦", AS:AS, "Empleado") ) - ( ( SUMIFS(AR:AR, AY:AY, INDIRECT("AE" & ROW()), AP:AP, "💲", AS:AS, "Familiar") + SUMIFS(AR:AR, AY:AY, INDIRECT("AE" & ROW()), AP:AP, "📦", AS:AS, "Familiar") ) / 2 ) - ( ( SUMIFS(AR:AR, AY:AY, INDIRECT("AE" & ROW()), AP:AP, "💲", AS:AS, "Exonerado ADH") + SUMIFS(AR:AR, AY:AY, INDIRECT("AE" & ROW()), AP:AP, "📦", AS:AS, "Exonerado ADH") ) / 2 ) - ( ( SUMIFS(AR:AR, AY:AY, INDIRECT("AE" & ROW()), AP:AP, "💲", AS:AS, "Exonerado Doctor") + SUMIFS(AR:AR, AY:AY, INDIRECT("AE" & ROW()), AP:AP, "📦", AS:AS, "Exonerado Doctor") ) / 2 ) -> 350 | AK15: =( SUMIFS(AR:AR, AY:AY, INDIRECT("AE" & ROW()), AP:AP, "💲") + SUMIFS(AR:AR, AY:AY, INDIRECT("AE" & ROW()), AP:AP, "📦") ) - ( SUMIFS(AR:AR, AY:AY, INDIRECT("AE" & ROW()), AP:AP, "💲", AS:AS, "Familiar") + SUMIFS(AR:AR, AY:AY, INDIRECT("AE" & ROW()), AP:AP, "📦", AS:AS, "Familiar") ) - ( SUMIFS(AR:AR, AY:AY, INDIRECT("AE" & ROW()), AP:AP, "💲", AS:AS, "Participante") + SUMIFS(AR:AR, AY:AY, INDIRECT("AE" & ROW()), AP:AP, "📦", AS:AS, "Participante") ) - ( SUMIFS(AR:AR, AY:AY, INDIRECT("AE" & ROW()), AP:AP, "💲", AS:AS, "Empleado") + SUMIFS(AR:AR, AY:AY, INDIRECT("AE" & ROW()), AP:AP, "📦", AS:AS, "Empleado") ) - ( SUMIFS(AR:AR, AY:AY, INDIRECT("AE" & ROW()), AP:AP, "💲", AS:AS, "Exonerado ADH") + SUMIFS(AR:AR, AY:AY, INDIRECT("AE" & ROW()), AP:AP, "📦", AS:AS, "Exonerado ADH") ) - (( SUMIFS(AR:AR, AY:AY, INDIRECT("AE" & ROW()), AP:AP, "💲", AS:AS, "Exonerado Doctor") + SUMIFS(AR:AR, AY:AY, INDIRECT("AE" & ROW()), AP:AP, "📦", AS:AS, "Exonerado Doctor") ) / 2 )- ( ( SUMIFS(AR:AR, AY:AY, INDIRECT("AE" & ROW()), AP:AP, "💲", AS:AS, "") + SUMIFS(AR:AR, AY:AY, INDIRECT("AE" & ROW()), AP:AP, "📦", AS:AS, "") ) / 2 ) -> 350 | AL15: =( SUMIFS(AR:AR, AY:AY, INDIRECT("AE" & ROW()), AP:AP, "💲") + SUMIFS(AR:AR, AY:AY, INDIRECT("AE" & ROW()), AP:AP, "📦") ) - (( SUMIFS(AR:AR, AY:AY, INDIRECT("AE" & ROW()), AP:AP, "💲", AS:AS, "Familiar") + SUMIFS(AR:AR, AY:AY, INDIRECT("AE" & ROW()), AP:AP, "📦", AS:AS, "Familiar") ) / 2 ) - (( SUMIFS(AR:AR, AY:AY, INDIRECT("AE" & ROW()), AP:AP, "💲", AS:AS, "Participante") + SUMIFS(AR:AR, AY:AY, INDIRECT("AE" & ROW()), AP:AP, "📦", AS:AS, "Participante") ) / 2 ) - (( SUMIFS(AR:AR, AY:AY, INDIRECT("AE" & ROW()), AP:AP, "💲", AS:AS, "Empleado") + SUMIFS(AR:AR, AY:AY, INDIRECT("AE" & ROW()), AP:AP, "📦", AS:AS, "Empleado") ) / 2 ) - (( SUMIFS(AR:AR, AY:AY, INDIRECT("AE" & ROW()), AP:AP, "💲", AS:AS, "Exonerado ADH") + SUMIFS(AR:AR, AY:AY, INDIRECT("AE" & ROW()), AP:AP, "📦", AS:AS, "Exonerado ADH") ) / 2 ) - ( SUMIFS(AR:AR, AY:AY, INDIRECT("AE" & ROW()), AP:AP, "💲", AS:AS, "Exonerado Doctor") + SUMIFS(AR:AR, AY:AY, INDIRECT("AE" & ROW()), AP:AP, "📦", AS:AS, "Exonerado Doctor") )- ( ( SUMIFS(AR:AR, AY:AY, INDIRECT("AE" & ROW()), AP:AP, "💲", AS:AS, "") + SUMIFS(AR:AR, AY:AY, INDIRECT("AE" & ROW()), AP:AP, "📦", AS:AS, "") ) / 2 ) -> 425 | AN15: =A4 -> 46266 | AO15: =C5 -> Consultorio N° 1 | AP15: =C42 -> 0 | AQ15: =D42 -> 0 | AR15: =U42 -> 0 | AS15: =S42 -> 0 | AT15: =S43 -> 0 | AU15: =U43 -> 0 | AV15: =S44 -> 0 | AW15: =U44 -> 0 | AX15: =U45 -> 0 | AY15: =F45 -> 0 | BF15: Nombre y Apellido | BG15: Personal ADH | BH15: Fecha | BI15: Monto | BJ15: Doctor
E16: Cedula: | F16: =IF(D14<>"", VLOOKUP(D14,'Base de Datos'!$A$2:$D1268,4,FALSE()),"") | I16: Cedula: | J16: =IF(H14<>"", VLOOKUP(H14,'Base de Datos'!$A$2:$D1268,4,FALSE()),"") -> V-10870603 | M16: Cedula: | N16: =IF(L14<>"", VLOOKUP(L14,'Base de Datos'!$A$2:$D1268,4,FALSE()),"") | P16: 📌 | Q16: Agendada | AE16: Luzmir Fagúndez | AG16: =COUNTIFS(AP:AP, "💲", AY:AY, AE16) + COUNTIFS(AP:AP, "📦", AY:AY, AE16) + COUNTIFS(AP:AP, "✅", AY:AY, AE16) -> 6 | AH16: =COUNTIFS(AP:AP, "💲", AY:AY, AE16) + COUNTIFS(AP:AP, "📦", AY:AY, AE16) -> 6 | AI16: =SUMIFS(AR:AR, AY:AY, AE16, AP:AP, "💲") + SUMIFS(AR:AR, AY:AY, AE16, AP:AP, "📦") -> 460 | AJ16: =( SUMIFS(AR:AR, AY:AY, INDIRECT("AE" & ROW()), AP:AP, "💲") + SUMIFS(AR:AR, AY:AY, INDIRECT("AE" & ROW()), AP:AP, "📦") ) - ( SUMIFS(AR:AR, AY:AY, INDIRECT("AE" & ROW()), AP:AP, "💲", AS:AS, "Participante") + SUMIFS(AR:AR, AY:AY, INDIRECT("AE" & ROW()), AP:AP, "📦", AS:AS, "Participante") ) - ( SUMIFS(AR:AR, AY:AY, INDIRECT("AE" & ROW()), AP:AP, "💲", AS:AS, "Empleado") + SUMIFS(AR:AR, AY:AY, INDIRECT("AE" & ROW()), AP:AP, "📦", AS:AS, "Empleado") ) - ( ( SUMIFS(AR:AR, AY:AY, INDIRECT("AE" & ROW()), AP:AP, "💲", AS:AS, "Familiar") + SUMIFS(AR:AR, AY:AY, INDIRECT("AE" & ROW()), AP:AP, "📦", AS:AS, "Familiar") ) / 2 ) - ( ( SUMIFS(AR:AR, AY:AY, INDIRECT("AE" & ROW()), AP:AP, "💲", AS:AS, "Exonerado ADH") + SUMIFS(AR:AR, AY:AY, INDIRECT("AE" & ROW()), AP:AP, "📦", AS:AS, "Exonerado ADH") ) / 2 ) - ( ( SUMIFS(AR:AR, AY:AY, INDIRECT("AE" & ROW()), AP:AP, "💲", AS:AS, "Exonerado Doctor") + SUMIFS(AR:AR, AY:AY, INDIRECT("AE" & ROW()), AP:AP, "📦", AS:AS, "Exonerado Doctor") ) / 2 ) -> 435 | AK16: =( SUMIFS(AR:AR, AY:AY, INDIRECT("AE" & ROW()), AP:AP, "💲") + SUMIFS(AR:AR, AY:AY, INDIRECT("AE" & ROW()), AP:AP, "📦") ) - ( SUMIFS(AR:AR, AY:AY, INDIRECT("AE" & ROW()), AP:AP, "💲", AS:AS, "Familiar") + SUMIFS(AR:AR, AY:AY, INDIRECT("AE" & ROW()), AP:AP, "📦", AS:AS, "Familiar") ) - ( SUMIFS(AR:AR, AY:AY, INDIRECT("AE" & ROW()), AP:AP, "💲", AS:AS, "Participante") + SUMIFS(AR:AR, AY:AY, INDIRECT("AE" & ROW()), AP:AP, "📦", AS:AS, "Participante") ) - ( SUMIFS(AR:AR, AY:AY, INDIRECT("AE" & ROW()), AP:AP, "💲", AS:AS, "Empleado") + SUMIFS(AR:AR, AY:AY, INDIRECT("AE" & ROW()), AP:AP, "📦", AS:AS, "Empleado") ) - ( SUMIFS(AR:AR, AY:AY, INDIRECT("AE" & ROW()), AP:AP, "💲", AS:AS, "Exonerado ADH") + SUMIFS(AR:AR, AY:AY, INDIRECT("AE" & ROW()), AP:AP, "📦", AS:AS, "Exonerado ADH") ) - (( SUMIFS(AR:AR, AY:AY, INDIRECT("AE" & ROW()), AP:AP, "💲", AS:AS, "Exonerado Doctor") + SUMIFS(AR:AR, AY:AY, INDIRECT("AE" & ROW()), AP:AP, "📦", AS:AS, "Exonerado Doctor") ) / 2 )- ( ( SUMIFS(AR:AR, AY:AY, INDIRECT("AE" & ROW()), AP:AP, "💲", AS:AS, "") + SUMIFS(AR:AR, AY:AY, INDIRECT("AE" & ROW()), AP:AP, "📦", AS:AS, "") ) / 2 ) -> 410 | AL16: =( SUMIFS(AR:AR, AY:AY, INDIRECT("AE" & ROW()), AP:AP, "💲") + SUMIFS(AR:AR, AY:AY, INDIRECT("AE" & ROW()), AP:AP, "📦") ) - (( SUMIFS(AR:AR, AY:AY, INDIRECT("AE" & ROW()), AP:AP, "💲", AS:AS, "Familiar") + SUMIFS(AR:AR, AY:AY, INDIRECT("AE" & ROW()), AP:AP, "📦", AS:AS, "Familiar") ) / 2 ) - (( SUMIFS(AR:AR, AY:AY, INDIRECT("AE" & ROW()), AP:AP, "💲", AS:AS, "Participante") + SUMIFS(AR:AR, AY:AY, INDIRECT("AE" & ROW()), AP:AP, "📦", AS:AS, "Participante") ) / 2 ) - (( SUMIFS(AR:AR, AY:AY, INDIRECT("AE" & ROW()), AP:AP, "💲", AS:AS, "Empleado") + SUMIFS(AR:AR, AY:AY, INDIRECT("AE" & ROW()), AP:AP, "📦", AS:AS, "Empleado") ) / 2 ) - (( SUMIFS(AR:AR, AY:AY, INDIRECT("AE" & ROW()), AP:AP, "💲", AS:AS, "Exonerado ADH") + SUMIFS(AR:AR, AY:AY, INDIRECT("AE" & ROW()), AP:AP, "📦", AS:AS, "Exonerado ADH") ) / 2 ) - ( SUMIFS(AR:AR, AY:AY, INDIRECT("AE" & ROW()), AP:AP, "💲", AS:AS, "Exonerado Doctor") + SUMIFS(AR:AR, AY:AY, INDIRECT("AE" & ROW()), AP:AP, "📦", AS:AS, "Exonerado Doctor") )- ( ( SUMIFS(AR:AR, AY:AY, INDIRECT("AE" & ROW()), AP:AP, "💲", AS:AS, "") + SUMIFS(AR:AR, AY:AY, INDIRECT("AE" & ROW()), AP:AP, "📦", AS:AS, "") ) / 2 ) -> 435 | AN16: =A4 -> 46266 | AO16: Consultorio N° 1 | AP16: =C46 -> 0 | AQ16: =D46 -> 0 | AR16: =U46 -> 0 | AS16: =S46 -> 0 | AT16: =S47 -> 0 | AU16: =U47 -> 0 | AV16: =S48 -> 0 | AW16: =U48 -> 0 | AX16: =U49 -> 0 | AY16: =F49 -> 0 | BF16: =IFERROR(__xludf.DUMMYFUNCTION("QUERY(AN:AY, ""SELECT AQ, AX, AN, AR, AY WHERE AS = 'Publicidad' AND (AP = '💲' OR AP = '📦') ORDER BY AN"", )"),"#N/A") -> #N/A
E17: Doctor: | I17: Doctor: | J17: Dra. Mónica Porras | M17: Doctor: | P17: 📞 | Q17: Sin confirmar | S17: =IF(OR(S14="Empleado",S14="Familiar"),"Nombre del Empleado","N° Factura") -> N° Factura | W17: =IF(OR(W14="Empleado",W14="Familiar"),"Nombre del Empleado","N° Factura") -> N° Factura | AA17: =IF(OR(AA14="Empleado",AA14="Familiar"),"Nombre del Empleado","N° Factura") -> N° Factura | AE17: Dra. Mariana Morales | AG17: =COUNTIFS(AP:AP, "💲", AY:AY, AE17) + COUNTIFS(AP:AP, "📦", AY:AY, AE17) + COUNTIFS(AP:AP, "✅", AY:AY, AE17) -> 0 | AH17: =COUNTIFS(AP:AP, "💲", AY:AY, AE17) + COUNTIFS(AP:AP, "📦", AY:AY, AE17) -> 0 | AI17: =SUMIFS(AR:AR, AY:AY, AE17, AP:AP, "💲") + SUMIFS(AR:AR, AY:AY, AE17, AP:AP, "📦") -> 0 | AJ17: =( SUMIFS(AR:AR, AY:AY, INDIRECT("AE" & ROW()), AP:AP, "💲") + SUMIFS(AR:AR, AY:AY, INDIRECT("AE" & ROW()), AP:AP, "📦") ) - ( SUMIFS(AR:AR, AY:AY, INDIRECT("AE" & ROW()), AP:AP, "💲", AS:AS, "Participante") + SUMIFS(AR:AR, AY:AY, INDIRECT("AE" & ROW()), AP:AP, "📦", AS:AS, "Participante") ) - ( SUMIFS(AR:AR, AY:AY, INDIRECT("AE" & ROW()), AP:AP, "💲", AS:AS, "Empleado") + SUMIFS(AR:AR, AY:AY, INDIRECT("AE" & ROW()), AP:AP, "📦", AS:AS, "Empleado") ) - ( ( SUMIFS(AR:AR, AY:AY, INDIRECT("AE" & ROW()), AP:AP, "💲", AS:AS, "Familiar") + SUMIFS(AR:AR, AY:AY, INDIRECT("AE" & ROW()), AP:AP, "📦", AS:AS, "Familiar") ) / 2 ) - ( ( SUMIFS(AR:AR, AY:AY, INDIRECT("AE" & ROW()), AP:AP, "💲", AS:AS, "Exonerado ADH") + SUMIFS(AR:AR, AY:AY, INDIRECT("AE" & ROW()), AP:AP, "📦", AS:AS, "Exonerado ADH") ) / 2 ) - ( ( SUMIFS(AR:AR, AY:AY, INDIRECT("AE" & ROW()), AP:AP, "💲", AS:AS, "Exonerado Doctor") + SUMIFS(AR:AR, AY:AY, INDIRECT("AE" & ROW()), AP:AP, "📦", AS:AS, "Exonerado Doctor") ) / 2 ) -> 0 | AK17: =( SUMIFS(AR:AR, AY:AY, INDIRECT("AE" & ROW()), AP:AP, "💲") + SUMIFS(AR:AR, AY:AY, INDIRECT("AE" & ROW()), AP:AP, "📦") ) - ( SUMIFS(AR:AR, AY:AY, INDIRECT("AE" & ROW()), AP:AP, "💲", AS:AS, "Familiar") + SUMIFS(AR:AR, AY:AY, INDIRECT("AE" & ROW()), AP:AP, "📦", AS:AS, "Familiar") ) - ( SUMIFS(AR:AR, AY:AY, INDIRECT("AE" & ROW()), AP:AP, "💲", AS:AS, "Participante") + SUMIFS(AR:AR, AY:AY, INDIRECT("AE" & ROW()), AP:AP, "📦", AS:AS, "Participante") ) - ( SUMIFS(AR:AR, AY:AY, INDIRECT("AE" & ROW()), AP:AP, "💲", AS:AS, "Empleado") + SUMIFS(AR:AR, AY:AY, INDIRECT("AE" & ROW()), AP:AP, "📦", AS:AS, "Empleado") ) - ( SUMIFS(AR:AR, AY:AY, INDIRECT("AE" & ROW()), AP:AP, "💲", AS:AS, "Exonerado ADH") + SUMIFS(AR:AR, AY:AY, INDIRECT("AE" & ROW()), AP:AP, "📦", AS:AS, "Exonerado ADH") ) - (( SUMIFS(AR:AR, AY:AY, INDIRECT("AE" & ROW()), AP:AP, "💲", AS:AS, "Exonerado Doctor") + SUMIFS(AR:AR, AY:AY, INDIRECT("AE" & ROW()), AP:AP, "📦", AS:AS, "Exonerado Doctor") ) / 2 )- ( ( SUMIFS(AR:AR, AY:AY, INDIRECT("AE" & ROW()), AP:AP, "💲", AS:AS, "") + SUMIFS(AR:AR, AY:AY, INDIRECT("AE" & ROW()), AP:AP, "📦", AS:AS, "") ) / 2 ) -> 0 | AL17: =( SUMIFS(AR:AR, AY:AY, INDIRECT("AE" & ROW()), AP:AP, "💲") + SUMIFS(AR:AR, AY:AY, INDIRECT("AE" & ROW()), AP:AP, "📦") ) - (( SUMIFS(AR:AR, AY:AY, INDIRECT("AE" & ROW()), AP:AP, "💲", AS:AS, "Familiar") + SUMIFS(AR:AR, AY:AY, INDIRECT("AE" & ROW()), AP:AP, "📦", AS:AS, "Familiar") ) / 2 ) - (( SUMIFS(AR:AR, AY:AY, INDIRECT("AE" & ROW()), AP:AP, "💲", AS:AS, "Participante") + SUMIFS(AR:AR, AY:AY, INDIRECT("AE" & ROW()), AP:AP, "📦", AS:AS, "Participante") ) / 2 ) - (( SUMIFS(AR:AR, AY:AY, INDIRECT("AE" & ROW()), AP:AP, "💲", AS:AS, "Empleado") + SUMIFS(AR:AR, AY:AY, INDIRECT("AE" & ROW()), AP:AP, "📦", AS:AS, "Empleado") ) / 2 ) - (( SUMIFS(AR:AR, AY:AY, INDIRECT("AE" & ROW()), AP:AP, "💲", AS:AS, "Exonerado ADH") + SUMIFS(AR:AR, AY:AY, INDIRECT("AE" & ROW()), AP:AP, "📦", AS:AS, "Exonerado ADH") ) / 2 ) - ( SUMIFS(AR:AR, AY:AY, INDIRECT("AE" & ROW()), AP:AP, "💲", AS:AS, "Exonerado Doctor") + SUMIFS(AR:AR, AY:AY, INDIRECT("AE" & ROW()), AP:AP, "📦", AS:AS, "Exonerado Doctor") )- ( ( SUMIFS(AR:AR, AY:AY, INDIRECT("AE" & ROW()), AP:AP, "💲", AS:AS, "") + SUMIFS(AR:AR, AY:AY, INDIRECT("AE" & ROW()), AP:AP, "📦", AS:AS, "") ) / 2 ) -> 0 | AN17: =A4 -> 46266 | AO17: Consultorio N° 1 | AP17: =C50 -> 0 | AQ17: =D50 -> 0 | AR17: =U50 -> 0 | AS17: =S50 -> 0 | AT17: =S51 -> 0 | AU17: =U51 -> 0 | AV17: =S52 -> 0 | AW17: =U52 -> 0 | AX17: =U53 -> 0 | AY17: =F53 -> 0
